{
 "cells": [
  {
   "cell_type": "code",
   "execution_count": 1,
   "metadata": {},
   "outputs": [],
   "source": [
    "import math\n",
    "\n",
    "import torch\n",
    "import pytorch_lightning as pl\n",
    "from filelock import FileLock\n",
    "from torch.utils.data import DataLoader, random_split\n",
    "from torch.nn import functional as F\n",
    "from torchvision.datasets import MNIST\n",
    "from torchvision import transforms\n",
    "import os"
   ]
  },
  {
   "cell_type": "code",
   "execution_count": 22,
   "metadata": {},
   "outputs": [],
   "source": [
    "class LightningMNISTClassifier(pl.LightningModule):\n",
    "    \"\"\"\n",
    "    This has been adapted from\n",
    "    https://towardsdatascience.com/from-pytorch-to-pytorch-lightning-a-gentle-introduction-b371b7caaf09\n",
    "    \"\"\"\n",
    "\n",
    "    def __init__(self, config, data_dir=None):\n",
    "        super(LightningMNISTClassifier, self).__init__()\n",
    "\n",
    "        self.data_dir = data_dir or os.getcwd()\n",
    "\n",
    "        self.layer_1_size = config[\"layer_1_size\"]\n",
    "        self.layer_2_size = config[\"layer_2_size\"]\n",
    "        self.lr = config[\"lr\"]\n",
    "        self.batch_size = config[\"batch_size\"]\n",
    "        self.validation_step_outputs = []\n",
    "        # mnist images are (1, 28, 28) (channels, width, height)\n",
    "        self.layer_1 = torch.nn.Linear(28 * 28, self.layer_1_size)\n",
    "        self.layer_2 = torch.nn.Linear(self.layer_1_size, self.layer_2_size)\n",
    "        self.layer_3 = torch.nn.Linear(self.layer_2_size, 10)\n",
    "\n",
    "    def forward(self, x):\n",
    "        batch_size, channels, width, height = x.size()\n",
    "        x = x.view(batch_size, -1)\n",
    "\n",
    "        x = self.layer_1(x)\n",
    "        x = torch.relu(x)\n",
    "\n",
    "        x = self.layer_2(x)\n",
    "        x = torch.relu(x)\n",
    "\n",
    "        x = self.layer_3(x)\n",
    "        x = torch.log_softmax(x, dim=1)\n",
    "\n",
    "        return x\n",
    "\n",
    "    def cross_entropy_loss(self, logits, labels):\n",
    "        return F.nll_loss(logits, labels)\n",
    "\n",
    "    def accuracy(self, logits, labels):\n",
    "        _, predicted = torch.max(logits.data, 1)\n",
    "        correct = (predicted == labels).sum().item()\n",
    "        accuracy = correct / len(labels)\n",
    "        return torch.tensor(accuracy)\n",
    "\n",
    "    def training_step(self, train_batch, batch_idx):\n",
    "        x, y = train_batch\n",
    "        logits = self.forward(x)\n",
    "        loss = self.cross_entropy_loss(logits, y)\n",
    "        accuracy = self.accuracy(logits, y)\n",
    "\n",
    "        self.log(\"loss\", loss)\n",
    "        self.log(\"ptl/train_accuracy\", accuracy)\n",
    "        return loss\n",
    "\n",
    "    def validation_step(self, val_batch, batch_idx):\n",
    "        x, y = val_batch\n",
    "        logits = self.forward(x)\n",
    "        loss = self.cross_entropy_loss(logits, y)\n",
    "        accuracy = self.accuracy(logits, y)\n",
    "        self.validation_step_outputs.append(loss)\n",
    "        return {\"loss\": loss, \"val_accuracy\": accuracy}\n",
    "\n",
    "    # def validation_epoch_end(self, outputs):\n",
    "    #     avg_loss = torch.stack([x[\"val_loss\"] for x in outputs]).mean()\n",
    "    #     avg_acc = torch.stack([x[\"val_accuracy\"] for x in outputs]).mean()\n",
    "    #     self.log(\"ptl/val_loss\", avg_loss)\n",
    "    #     self.log(\"ptl/val_accuracy\", avg_acc)\n",
    "\n",
    "    def on_validation_epoch_end(self):\n",
    "        epoch_average = torch.stack(self.validation_step_outputs).mean()\n",
    "        self.log(\"loss\", epoch_average)\n",
    "        self.validation_step_outputs.clear()  # free memory\n",
    "\n",
    "    @staticmethod\n",
    "    def download_data(data_dir):\n",
    "        transform = transforms.Compose(\n",
    "            [transforms.ToTensor(), transforms.Normalize((0.1307,), (0.3081,))]\n",
    "        )\n",
    "        with FileLock(os.path.expanduser(\"~/.data.lock\")):\n",
    "            return MNIST(data_dir, train=True, download=True, transform=transform)\n",
    "\n",
    "    def prepare_data(self):\n",
    "        mnist_train = self.download_data(self.data_dir)\n",
    "\n",
    "        self.mnist_train, self.mnist_val = random_split(mnist_train, [55000, 5000])\n",
    "\n",
    "    def train_dataloader(self):\n",
    "        return DataLoader(self.mnist_train, batch_size=int(self.batch_size))\n",
    "\n",
    "    def val_dataloader(self):\n",
    "        return DataLoader(self.mnist_val, batch_size=int(self.batch_size))\n",
    "\n",
    "    def configure_optimizers(self):\n",
    "        optimizer = torch.optim.Adam(self.parameters(), lr=self.lr)\n",
    "        return optimizer\n",
    "\n",
    "\n",
    "def train_mnist(config):\n",
    "    model = LightningMNISTClassifier(config)\n",
    "    trainer = pl.Trainer(max_epochs=10, enable_progress_bar=False)\n",
    "\n",
    "    trainer.fit(model)"
   ]
  },
  {
   "cell_type": "code",
   "execution_count": 3,
   "metadata": {},
   "outputs": [],
   "source": [
    "def train_mnist_no_tune():\n",
    "    config = {\"layer_1_size\": 128, \"layer_2_size\": 256, \"lr\": 1e-3, \"batch_size\": 64}\n",
    "    train_mnist(config)"
   ]
  },
  {
   "cell_type": "code",
   "execution_count": 7,
   "metadata": {},
   "outputs": [],
   "source": [
    "from pytorch_lightning.loggers import TensorBoardLogger\n",
    "from ray import train, tune\n",
    "from ray.tune import CLIReporter\n",
    "from ray.tune.schedulers import ASHAScheduler, PopulationBasedTraining\n",
    "from ray.tune.integration.pytorch_lightning import (\n",
    "    TuneReportCallback,\n",
    "    TuneReportCheckpointCallback,\n",
    ")"
   ]
  },
  {
   "cell_type": "code",
   "execution_count": 8,
   "metadata": {},
   "outputs": [],
   "source": [
    "def train_mnist_tune(config, num_epochs=10, num_gpus=0, data_dir=\"~/data\"):\n",
    "    data_dir = os.path.expanduser(data_dir)\n",
    "    model = LightningMNISTClassifier(config, data_dir)\n",
    "    trainer = pl.Trainer(\n",
    "        max_epochs=num_epochs,\n",
    "        # If fractional GPUs passed in, convert to int.\n",
    "        gpus=math.ceil(num_gpus),\n",
    "        logger=TensorBoardLogger(save_dir=os.getcwd(), name=\"\", version=\".\"),\n",
    "        enable_progress_bar=False,\n",
    "        callbacks=[\n",
    "            TuneReportCallback(\n",
    "                {\"loss\": \"loss\", \"mean_accuracy\": \"ptl/val_accuracy\"},\n",
    "                on=\"validation_end\",\n",
    "            )\n",
    "        ],\n",
    "    )\n",
    "    trainer.fit(model)"
   ]
  },
  {
   "cell_type": "code",
   "execution_count": 9,
   "metadata": {},
   "outputs": [],
   "source": [
    "config = {\n",
    "    \"layer_1_size\": tune.choice([32, 64, 128]),\n",
    "    \"layer_2_size\": tune.choice([64, 128, 256]),\n",
    "    \"lr\": tune.loguniform(1e-4, 1e-1),\n",
    "    \"batch_size\": tune.choice([32, 64, 128]),\n",
    "}"
   ]
  },
  {
   "cell_type": "code",
   "execution_count": 10,
   "metadata": {},
   "outputs": [],
   "source": [
    "num_epochs = 10\n",
    "\n",
    "scheduler = ASHAScheduler(max_t=num_epochs, grace_period=1, reduction_factor=2)"
   ]
  },
  {
   "cell_type": "code",
   "execution_count": 11,
   "metadata": {},
   "outputs": [],
   "source": [
    "reporter = CLIReporter(\n",
    "    parameter_columns=[\"layer_1_size\", \"layer_2_size\", \"lr\", \"batch_size\"],\n",
    "    metric_columns=[\"loss\", \"mean_accuracy\", \"training_iteration\"],\n",
    ")"
   ]
  },
  {
   "cell_type": "code",
   "execution_count": 14,
   "metadata": {},
   "outputs": [],
   "source": [
    "gpus_per_trial = 0\n",
    "data_dir = \"~/data\"\n",
    "\n",
    "train_fn_with_parameters = tune.with_parameters(\n",
    "    train_mnist_tune, num_epochs=num_epochs, num_gpus=gpus_per_trial, data_dir=data_dir\n",
    ")"
   ]
  },
  {
   "cell_type": "code",
   "execution_count": 15,
   "metadata": {},
   "outputs": [],
   "source": [
    "resources_per_trial = {\"cpu\": 1, \"gpu\": gpus_per_trial}"
   ]
  },
  {
   "cell_type": "code",
   "execution_count": 23,
   "metadata": {},
   "outputs": [],
   "source": [
    "def tune_mnist_asha(num_samples=10, num_epochs=10, gpus_per_trial=0, data_dir=\"~/data\"):\n",
    "    config = {\n",
    "        \"layer_1_size\": tune.choice([32, 64, 128]),\n",
    "        \"layer_2_size\": tune.choice([64, 128, 256]),\n",
    "        \"lr\": tune.loguniform(1e-4, 1e-1),\n",
    "        \"batch_size\": tune.choice([32, 64, 128]),\n",
    "    }\n",
    "\n",
    "    scheduler = ASHAScheduler(max_t=num_epochs, grace_period=1, reduction_factor=2)\n",
    "\n",
    "    reporter = CLIReporter(\n",
    "        parameter_columns=[\"layer_1_size\", \"layer_2_size\", \"lr\", \"batch_size\"],\n",
    "        metric_columns=[\"loss\", \"mean_accuracy\", \"training_iteration\"],\n",
    "    )\n",
    "\n",
    "    train_fn_with_parameters = tune.with_parameters(\n",
    "        train_mnist_tune,\n",
    "        num_epochs=num_epochs,\n",
    "        num_gpus=gpus_per_trial,\n",
    "        data_dir=data_dir,\n",
    "    )\n",
    "    resources_per_trial = {\"cpu\": 1, \"gpu\": gpus_per_trial}\n",
    "\n",
    "    tuner = tune.Tuner(\n",
    "        tune.with_resources(train_fn_with_parameters, resources=resources_per_trial),\n",
    "        tune_config=tune.TuneConfig(\n",
    "            metric=\"loss\",\n",
    "            mode=\"min\",\n",
    "            scheduler=scheduler,\n",
    "            num_samples=num_samples,\n",
    "        ),\n",
    "        run_config=train.RunConfig(\n",
    "            name=\"tune_mnist_asha\",\n",
    "            progress_reporter=reporter,\n",
    "        ),\n",
    "        param_space=config,\n",
    "    )\n",
    "    results = tuner.fit()\n",
    "\n",
    "    print(\"Best hyperparameters found were: \", results.get_best_result().config)"
   ]
  },
  {
   "cell_type": "code",
   "execution_count": 24,
   "metadata": {},
   "outputs": [
    {
     "name": "stderr",
     "output_type": "stream",
     "text": [
      "2023-12-07 11:28:31,153\tINFO tune.py:586 -- [output] This uses the legacy output and progress reporter, as Jupyter notebooks are not supported by the new engine, yet. For more information, please see https://github.com/ray-project/ray/issues/36949\n"
     ]
    },
    {
     "name": "stdout",
     "output_type": "stream",
     "text": [
      "== Status ==\n",
      "Current time: 2023-12-07 11:28:31 (running for 00:00:00.16)\n",
      "Using AsyncHyperBand: num_stopped=0\n",
      "Bracket: Iter 8.000: None | Iter 4.000: None | Iter 2.000: None | Iter 1.000: None\n",
      "Logical resource usage: 10.0/12 CPUs, 0/1 GPUs (0.0/1.0 accelerator_type:G)\n",
      "Result logdir: /home/gediminas/ray_results/tune_mnist_asha\n",
      "Number of trials: 10/10 (10 PENDING)\n",
      "\n",
      "\n"
     ]
    },
    {
     "name": "stderr",
     "output_type": "stream",
     "text": [
      "\u001b[36m(train_mnist_tune pid=22216)\u001b[0m /home/gediminas/anaconda3/envs/DL/lib/python3.11/site-packages/ray/tune/integration/pytorch_lightning.py:194: `ray.tune.integration.pytorch_lightning.TuneReportCallback` is deprecated. Use `ray.tune.integration.pytorch_lightning.TuneReportCheckpointCallback` instead.\n",
      "2023-12-07 11:28:34,782\tERROR tune_controller.py:1383 -- Trial task failed for trial train_mnist_tune_fc4ed_00005\n",
      "Traceback (most recent call last):\n",
      "  File \"/home/gediminas/anaconda3/envs/DL/lib/python3.11/site-packages/ray/air/execution/_internal/event_manager.py\", line 110, in resolve_future\n",
      "    result = ray.get(future)\n",
      "             ^^^^^^^^^^^^^^^\n",
      "  File \"/home/gediminas/anaconda3/envs/DL/lib/python3.11/site-packages/ray/_private/auto_init_hook.py\", line 24, in auto_init_wrapper\n",
      "    return fn(*args, **kwargs)\n",
      "           ^^^^^^^^^^^^^^^^^^^\n",
      "  File \"/home/gediminas/anaconda3/envs/DL/lib/python3.11/site-packages/ray/_private/client_mode_hook.py\", line 103, in wrapper\n",
      "    return func(*args, **kwargs)\n",
      "           ^^^^^^^^^^^^^^^^^^^^^\n",
      "  File \"/home/gediminas/anaconda3/envs/DL/lib/python3.11/site-packages/ray/_private/worker.py\", line 2563, in get\n",
      "    raise value.as_instanceof_cause()\n",
      "ray.exceptions.RayTaskError(TypeError): \u001b[36mray::ImplicitFunc.train()\u001b[39m (pid=22216, ip=192.168.0.103, actor_id=3bf651ec1aaf2a32e2df3ffe01000000, repr=train_mnist_tune)\n",
      "           ^^^^^^^^^^^^^^^^^^^^^^^^^^^^^^^^^^^^\n",
      "           ^^^^^^^^^^^^^^^^^^^^^^^^^^^^^^^\n",
      "  File \"/home/gediminas/anaconda3/envs/DL/lib/python3.11/site-packages/ray/tune/trainable/trainable.py\", line 342, in train\n",
      "    raise skipped from exception_cause(skipped)\n",
      "  File \"/home/gediminas/anaconda3/envs/DL/lib/python3.11/site-packages/ray/air/_internal/util.py\", line 91, in run\n",
      "    self._ret = self._target(*self._args, **self._kwargs)\n",
      "                ^^^^^^^^^^^^^^^^^^^^^^^^^^^^^^^^^^^^^^^^^\n",
      "  File \"/home/gediminas/anaconda3/envs/DL/lib/python3.11/site-packages/ray/tune/trainable/function_trainable.py\", line 115, in <lambda>\n",
      "    training_func=lambda: self._trainable_func(self.config),\n",
      "                          ^^^^^^^^^^^^^^^^^^^^^^^^^^^^^^^^^\n",
      "           ^^^^^^^^^^^^^^^^^^^^^^^^^^^^^^^\n",
      "  File \"/home/gediminas/anaconda3/envs/DL/lib/python3.11/site-packages/ray/tune/trainable/function_trainable.py\", line 332, in _trainable_func\n",
      "    output = fn()\n",
      "             ^^^^\n",
      "  File \"/home/gediminas/anaconda3/envs/DL/lib/python3.11/site-packages/ray/tune/trainable/util.py\", line 321, in inner\n",
      "    return trainable(config, **fn_kwargs)\n",
      "           ^^^^^^^^^^^^^^^^^^^^^^^^^^^^^^\n",
      "  File \"/tmp/ipykernel_20077/685680896.py\", line 4, in train_mnist_tune\n",
      "  File \"/home/gediminas/anaconda3/envs/DL/lib/python3.11/site-packages/pytorch_lightning/utilities/argparse.py\", line 70, in insert_env_defaults\n",
      "    return fn(self, **kwargs)\n",
      "           ^^^^^^^^^^^^^^^^^^\n",
      "TypeError: Trainer.__init__() got an unexpected keyword argument 'gpus'\n",
      "2023-12-07 11:28:34,787\tERROR tune_controller.py:1383 -- Trial task failed for trial train_mnist_tune_fc4ed_00004\n",
      "Traceback (most recent call last):\n",
      "  File \"/home/gediminas/anaconda3/envs/DL/lib/python3.11/site-packages/ray/air/execution/_internal/event_manager.py\", line 110, in resolve_future\n",
      "    result = ray.get(future)\n",
      "             ^^^^^^^^^^^^^^^\n",
      "  File \"/home/gediminas/anaconda3/envs/DL/lib/python3.11/site-packages/ray/_private/auto_init_hook.py\", line 24, in auto_init_wrapper\n",
      "    return fn(*args, **kwargs)\n",
      "           ^^^^^^^^^^^^^^^^^^^\n",
      "  File \"/home/gediminas/anaconda3/envs/DL/lib/python3.11/site-packages/ray/_private/client_mode_hook.py\", line 103, in wrapper\n",
      "    return func(*args, **kwargs)\n",
      "           ^^^^^^^^^^^^^^^^^^^^^\n",
      "  File \"/home/gediminas/anaconda3/envs/DL/lib/python3.11/site-packages/ray/_private/worker.py\", line 2563, in get\n",
      "    raise value.as_instanceof_cause()\n",
      "ray.exceptions.RayTaskError(TypeError): \u001b[36mray::ImplicitFunc.train()\u001b[39m (pid=22214, ip=192.168.0.103, actor_id=1928e06606c1a73f4548195501000000, repr=train_mnist_tune)\n",
      "           ^^^^^^^^^^^^^^^^^^^^^^^^^^^^^^^^^^^^\n",
      "           ^^^^^^^^^^^^^^^^^^^^^^^^^^^^^^^\n",
      "  File \"/home/gediminas/anaconda3/envs/DL/lib/python3.11/site-packages/ray/tune/trainable/trainable.py\", line 342, in train\n",
      "    raise skipped from exception_cause(skipped)\n",
      "  File \"/home/gediminas/anaconda3/envs/DL/lib/python3.11/site-packages/ray/air/_internal/util.py\", line 91, in run\n",
      "    self._ret = self._target(*self._args, **self._kwargs)\n",
      "                ^^^^^^^^^^^^^^^^^^^^^^^^^^^^^^^^^^^^^^^^^\n",
      "  File \"/home/gediminas/anaconda3/envs/DL/lib/python3.11/site-packages/ray/tune/trainable/function_trainable.py\", line 115, in <lambda>\n",
      "    training_func=lambda: self._trainable_func(self.config),\n",
      "                          ^^^^^^^^^^^^^^^^^^^^^^^^^^^^^^^^^\n",
      "           ^^^^^^^^^^^^^^^^^^^^^^^^^^^^^^^\n",
      "  File \"/home/gediminas/anaconda3/envs/DL/lib/python3.11/site-packages/ray/tune/trainable/function_trainable.py\", line 332, in _trainable_func\n",
      "    output = fn()\n",
      "             ^^^^\n",
      "  File \"/home/gediminas/anaconda3/envs/DL/lib/python3.11/site-packages/ray/tune/trainable/util.py\", line 321, in inner\n",
      "    return trainable(config, **fn_kwargs)\n",
      "           ^^^^^^^^^^^^^^^^^^^^^^^^^^^^^^\n",
      "  File \"/tmp/ipykernel_20077/685680896.py\", line 4, in train_mnist_tune\n",
      "  File \"/home/gediminas/anaconda3/envs/DL/lib/python3.11/site-packages/pytorch_lightning/utilities/argparse.py\", line 70, in insert_env_defaults\n",
      "    return fn(self, **kwargs)\n",
      "           ^^^^^^^^^^^^^^^^^^\n",
      "TypeError: Trainer.__init__() got an unexpected keyword argument 'gpus'\n",
      "2023-12-07 11:28:34,923\tERROR tune_controller.py:1383 -- Trial task failed for trial train_mnist_tune_fc4ed_00000\n",
      "Traceback (most recent call last):\n",
      "  File \"/home/gediminas/anaconda3/envs/DL/lib/python3.11/site-packages/ray/air/execution/_internal/event_manager.py\", line 110, in resolve_future\n",
      "    result = ray.get(future)\n",
      "             ^^^^^^^^^^^^^^^\n",
      "  File \"/home/gediminas/anaconda3/envs/DL/lib/python3.11/site-packages/ray/_private/auto_init_hook.py\", line 24, in auto_init_wrapper\n",
      "    return fn(*args, **kwargs)\n",
      "           ^^^^^^^^^^^^^^^^^^^\n",
      "  File \"/home/gediminas/anaconda3/envs/DL/lib/python3.11/site-packages/ray/_private/client_mode_hook.py\", line 103, in wrapper\n",
      "    return func(*args, **kwargs)\n",
      "           ^^^^^^^^^^^^^^^^^^^^^\n",
      "  File \"/home/gediminas/anaconda3/envs/DL/lib/python3.11/site-packages/ray/_private/worker.py\", line 2563, in get\n",
      "    raise value.as_instanceof_cause()\n",
      "ray.exceptions.RayTaskError(TypeError): \u001b[36mray::ImplicitFunc.train()\u001b[39m (pid=22211, ip=192.168.0.103, actor_id=4baa6c309f4493e9c6937efd01000000, repr=train_mnist_tune)\n",
      "           ^^^^^^^^^^^^^^^^^^^^^^^^^^^^^^^^^^^^\n",
      "           ^^^^^^^^^^^^^^^^^^^^^^^^^^^^^^^\n",
      "  File \"/home/gediminas/anaconda3/envs/DL/lib/python3.11/site-packages/ray/tune/trainable/trainable.py\", line 342, in train\n",
      "    raise skipped from exception_cause(skipped)\n",
      "  File \"/home/gediminas/anaconda3/envs/DL/lib/python3.11/site-packages/ray/air/_internal/util.py\", line 91, in run\n",
      "    self._ret = self._target(*self._args, **self._kwargs)\n",
      "                ^^^^^^^^^^^^^^^^^^^^^^^^^^^^^^^^^^^^^^^^^\n",
      "  File \"/home/gediminas/anaconda3/envs/DL/lib/python3.11/site-packages/ray/tune/trainable/function_trainable.py\", line 115, in <lambda>\n",
      "    training_func=lambda: self._trainable_func(self.config),\n",
      "                          ^^^^^^^^^^^^^^^^^^^^^^^^^^^^^^^^^\n",
      "           ^^^^^^^^^^^^^^^^^^^^^^^^^^^^^^^\n",
      "  File \"/home/gediminas/anaconda3/envs/DL/lib/python3.11/site-packages/ray/tune/trainable/function_trainable.py\", line 332, in _trainable_func\n",
      "    output = fn()\n",
      "             ^^^^\n",
      "  File \"/home/gediminas/anaconda3/envs/DL/lib/python3.11/site-packages/ray/tune/trainable/util.py\", line 321, in inner\n",
      "    return trainable(config, **fn_kwargs)\n",
      "           ^^^^^^^^^^^^^^^^^^^^^^^^^^^^^^\n",
      "  File \"/tmp/ipykernel_20077/685680896.py\", line 4, in train_mnist_tune\n",
      "  File \"/home/gediminas/anaconda3/envs/DL/lib/python3.11/site-packages/pytorch_lightning/utilities/argparse.py\", line 70, in insert_env_defaults\n",
      "    return fn(self, **kwargs)\n",
      "           ^^^^^^^^^^^^^^^^^^\n",
      "TypeError: Trainer.__init__() got an unexpected keyword argument 'gpus'\n",
      "2023-12-07 11:28:34,931\tERROR tune_controller.py:1383 -- Trial task failed for trial train_mnist_tune_fc4ed_00002\n",
      "Traceback (most recent call last):\n",
      "  File \"/home/gediminas/anaconda3/envs/DL/lib/python3.11/site-packages/ray/air/execution/_internal/event_manager.py\", line 110, in resolve_future\n",
      "    result = ray.get(future)\n",
      "             ^^^^^^^^^^^^^^^\n",
      "  File \"/home/gediminas/anaconda3/envs/DL/lib/python3.11/site-packages/ray/_private/auto_init_hook.py\", line 24, in auto_init_wrapper\n",
      "    return fn(*args, **kwargs)\n",
      "           ^^^^^^^^^^^^^^^^^^^\n",
      "  File \"/home/gediminas/anaconda3/envs/DL/lib/python3.11/site-packages/ray/_private/client_mode_hook.py\", line 103, in wrapper\n",
      "    return func(*args, **kwargs)\n",
      "           ^^^^^^^^^^^^^^^^^^^^^\n",
      "  File \"/home/gediminas/anaconda3/envs/DL/lib/python3.11/site-packages/ray/_private/worker.py\", line 2563, in get\n",
      "    raise value.as_instanceof_cause()\n",
      "ray.exceptions.RayTaskError(TypeError): \u001b[36mray::ImplicitFunc.train()\u001b[39m (pid=22213, ip=192.168.0.103, actor_id=3a3ce3e45b578d4c8b1dbab101000000, repr=train_mnist_tune)\n",
      "           ^^^^^^^^^^^^^^^^^^^^^^^^^^^^^^^^^^^^\n",
      "           ^^^^^^^^^^^^^^^^^^^^^^^^^^^^^^^\n",
      "  File \"/home/gediminas/anaconda3/envs/DL/lib/python3.11/site-packages/ray/tune/trainable/trainable.py\", line 342, in train\n",
      "    raise skipped from exception_cause(skipped)\n",
      "  File \"/home/gediminas/anaconda3/envs/DL/lib/python3.11/site-packages/ray/air/_internal/util.py\", line 91, in run\n",
      "    self._ret = self._target(*self._args, **self._kwargs)\n",
      "                ^^^^^^^^^^^^^^^^^^^^^^^^^^^^^^^^^^^^^^^^^\n",
      "  File \"/home/gediminas/anaconda3/envs/DL/lib/python3.11/site-packages/ray/tune/trainable/function_trainable.py\", line 115, in <lambda>\n",
      "    training_func=lambda: self._trainable_func(self.config),\n",
      "                          ^^^^^^^^^^^^^^^^^^^^^^^^^^^^^^^^^\n",
      "           ^^^^^^^^^^^^^^^^^^^^^^^^^^^^^^^\n",
      "  File \"/home/gediminas/anaconda3/envs/DL/lib/python3.11/site-packages/ray/tune/trainable/function_trainable.py\", line 332, in _trainable_func\n",
      "    output = fn()\n",
      "             ^^^^\n",
      "  File \"/home/gediminas/anaconda3/envs/DL/lib/python3.11/site-packages/ray/tune/trainable/util.py\", line 321, in inner\n",
      "    return trainable(config, **fn_kwargs)\n",
      "           ^^^^^^^^^^^^^^^^^^^^^^^^^^^^^^\n",
      "  File \"/tmp/ipykernel_20077/685680896.py\", line 4, in train_mnist_tune\n",
      "  File \"/home/gediminas/anaconda3/envs/DL/lib/python3.11/site-packages/pytorch_lightning/utilities/argparse.py\", line 70, in insert_env_defaults\n",
      "    return fn(self, **kwargs)\n",
      "           ^^^^^^^^^^^^^^^^^^\n",
      "TypeError: Trainer.__init__() got an unexpected keyword argument 'gpus'\n",
      "2023-12-07 11:28:34,980\tERROR tune_controller.py:1383 -- Trial task failed for trial train_mnist_tune_fc4ed_00006\n",
      "Traceback (most recent call last):\n",
      "  File \"/home/gediminas/anaconda3/envs/DL/lib/python3.11/site-packages/ray/air/execution/_internal/event_manager.py\", line 110, in resolve_future\n",
      "    result = ray.get(future)\n",
      "             ^^^^^^^^^^^^^^^\n",
      "  File \"/home/gediminas/anaconda3/envs/DL/lib/python3.11/site-packages/ray/_private/auto_init_hook.py\", line 24, in auto_init_wrapper\n",
      "    return fn(*args, **kwargs)\n",
      "           ^^^^^^^^^^^^^^^^^^^\n",
      "  File \"/home/gediminas/anaconda3/envs/DL/lib/python3.11/site-packages/ray/_private/client_mode_hook.py\", line 103, in wrapper\n",
      "    return func(*args, **kwargs)\n",
      "           ^^^^^^^^^^^^^^^^^^^^^\n",
      "  File \"/home/gediminas/anaconda3/envs/DL/lib/python3.11/site-packages/ray/_private/worker.py\", line 2563, in get\n",
      "    raise value.as_instanceof_cause()\n",
      "ray.exceptions.RayTaskError(TypeError): \u001b[36mray::ImplicitFunc.train()\u001b[39m (pid=22217, ip=192.168.0.103, actor_id=f8d02cc6c1eaac037560991701000000, repr=train_mnist_tune)\n",
      "           ^^^^^^^^^^^^^^^^^^^^^^^^^^^^^^^^^^^^\n",
      "           ^^^^^^^^^^^^^^^^^^^^^^^^^^^^^^^\n",
      "  File \"/home/gediminas/anaconda3/envs/DL/lib/python3.11/site-packages/ray/tune/trainable/trainable.py\", line 342, in train\n",
      "    raise skipped from exception_cause(skipped)\n",
      "  File \"/home/gediminas/anaconda3/envs/DL/lib/python3.11/site-packages/ray/air/_internal/util.py\", line 91, in run\n",
      "    self._ret = self._target(*self._args, **self._kwargs)\n",
      "                ^^^^^^^^^^^^^^^^^^^^^^^^^^^^^^^^^^^^^^^^^\n",
      "  File \"/home/gediminas/anaconda3/envs/DL/lib/python3.11/site-packages/ray/tune/trainable/function_trainable.py\", line 115, in <lambda>\n",
      "    training_func=lambda: self._trainable_func(self.config),\n",
      "                          ^^^^^^^^^^^^^^^^^^^^^^^^^^^^^^^^^\n",
      "           ^^^^^^^^^^^^^^^^^^^^^^^^^^^^^^^\n",
      "  File \"/home/gediminas/anaconda3/envs/DL/lib/python3.11/site-packages/ray/tune/trainable/function_trainable.py\", line 332, in _trainable_func\n",
      "    output = fn()\n",
      "             ^^^^\n",
      "  File \"/home/gediminas/anaconda3/envs/DL/lib/python3.11/site-packages/ray/tune/trainable/util.py\", line 321, in inner\n",
      "    return trainable(config, **fn_kwargs)\n",
      "           ^^^^^^^^^^^^^^^^^^^^^^^^^^^^^^\n",
      "  File \"/tmp/ipykernel_20077/685680896.py\", line 4, in train_mnist_tune\n",
      "  File \"/home/gediminas/anaconda3/envs/DL/lib/python3.11/site-packages/pytorch_lightning/utilities/argparse.py\", line 70, in insert_env_defaults\n",
      "    return fn(self, **kwargs)\n",
      "           ^^^^^^^^^^^^^^^^^^\n",
      "TypeError: Trainer.__init__() got an unexpected keyword argument 'gpus'\n",
      "2023-12-07 11:28:35,027\tERROR tune_controller.py:1383 -- Trial task failed for trial train_mnist_tune_fc4ed_00008\n",
      "Traceback (most recent call last):\n",
      "  File \"/home/gediminas/anaconda3/envs/DL/lib/python3.11/site-packages/ray/air/execution/_internal/event_manager.py\", line 110, in resolve_future\n",
      "    result = ray.get(future)\n",
      "             ^^^^^^^^^^^^^^^\n",
      "  File \"/home/gediminas/anaconda3/envs/DL/lib/python3.11/site-packages/ray/_private/auto_init_hook.py\", line 24, in auto_init_wrapper\n",
      "    return fn(*args, **kwargs)\n",
      "           ^^^^^^^^^^^^^^^^^^^\n",
      "  File \"/home/gediminas/anaconda3/envs/DL/lib/python3.11/site-packages/ray/_private/client_mode_hook.py\", line 103, in wrapper\n",
      "    return func(*args, **kwargs)\n",
      "           ^^^^^^^^^^^^^^^^^^^^^\n",
      "  File \"/home/gediminas/anaconda3/envs/DL/lib/python3.11/site-packages/ray/_private/worker.py\", line 2563, in get\n",
      "    raise value.as_instanceof_cause()\n",
      "ray.exceptions.RayTaskError(TypeError): \u001b[36mray::ImplicitFunc.train()\u001b[39m (pid=22219, ip=192.168.0.103, actor_id=c2a133435cf4f51e0131e1dd01000000, repr=train_mnist_tune)\n",
      "           ^^^^^^^^^^^^^^^^^^^^^^^^^^^^^^^^^^^^\n",
      "           ^^^^^^^^^^^^^^^^^^^^^^^^^^^^^^^\n",
      "  File \"/home/gediminas/anaconda3/envs/DL/lib/python3.11/site-packages/ray/tune/trainable/trainable.py\", line 342, in train\n",
      "    raise skipped from exception_cause(skipped)\n",
      "  File \"/home/gediminas/anaconda3/envs/DL/lib/python3.11/site-packages/ray/air/_internal/util.py\", line 91, in run\n",
      "    self._ret = self._target(*self._args, **self._kwargs)\n",
      "                ^^^^^^^^^^^^^^^^^^^^^^^^^^^^^^^^^^^^^^^^^\n",
      "  File \"/home/gediminas/anaconda3/envs/DL/lib/python3.11/site-packages/ray/tune/trainable/function_trainable.py\", line 115, in <lambda>\n",
      "    training_func=lambda: self._trainable_func(self.config),\n",
      "                          ^^^^^^^^^^^^^^^^^^^^^^^^^^^^^^^^^\n",
      "           ^^^^^^^^^^^^^^^^^^^^^^^^^^^^^^^\n",
      "  File \"/home/gediminas/anaconda3/envs/DL/lib/python3.11/site-packages/ray/tune/trainable/function_trainable.py\", line 332, in _trainable_func\n",
      "    output = fn()\n",
      "             ^^^^\n",
      "  File \"/home/gediminas/anaconda3/envs/DL/lib/python3.11/site-packages/ray/tune/trainable/util.py\", line 321, in inner\n",
      "    return trainable(config, **fn_kwargs)\n",
      "           ^^^^^^^^^^^^^^^^^^^^^^^^^^^^^^\n",
      "  File \"/tmp/ipykernel_20077/685680896.py\", line 4, in train_mnist_tune\n",
      "  File \"/home/gediminas/anaconda3/envs/DL/lib/python3.11/site-packages/pytorch_lightning/utilities/argparse.py\", line 70, in insert_env_defaults\n",
      "    return fn(self, **kwargs)\n",
      "           ^^^^^^^^^^^^^^^^^^\n",
      "TypeError: Trainer.__init__() got an unexpected keyword argument 'gpus'\n",
      "2023-12-07 11:28:35,036\tERROR tune_controller.py:1383 -- Trial task failed for trial train_mnist_tune_fc4ed_00001\n",
      "Traceback (most recent call last):\n",
      "  File \"/home/gediminas/anaconda3/envs/DL/lib/python3.11/site-packages/ray/air/execution/_internal/event_manager.py\", line 110, in resolve_future\n",
      "    result = ray.get(future)\n",
      "             ^^^^^^^^^^^^^^^\n",
      "  File \"/home/gediminas/anaconda3/envs/DL/lib/python3.11/site-packages/ray/_private/auto_init_hook.py\", line 24, in auto_init_wrapper\n",
      "    return fn(*args, **kwargs)\n",
      "           ^^^^^^^^^^^^^^^^^^^\n",
      "  File \"/home/gediminas/anaconda3/envs/DL/lib/python3.11/site-packages/ray/_private/client_mode_hook.py\", line 103, in wrapper\n",
      "    return func(*args, **kwargs)\n",
      "           ^^^^^^^^^^^^^^^^^^^^^\n",
      "  File \"/home/gediminas/anaconda3/envs/DL/lib/python3.11/site-packages/ray/_private/worker.py\", line 2563, in get\n",
      "    raise value.as_instanceof_cause()\n",
      "ray.exceptions.RayTaskError(TypeError): \u001b[36mray::ImplicitFunc.train()\u001b[39m (pid=22212, ip=192.168.0.103, actor_id=fff53f24a31db2fd1c3164a601000000, repr=train_mnist_tune)\n",
      "           ^^^^^^^^^^^^^^^^^^^^^^^^^^^^^^^^^^^^\n",
      "           ^^^^^^^^^^^^^^^^^^^^^^^^^^^^^^^\n",
      "  File \"/home/gediminas/anaconda3/envs/DL/lib/python3.11/site-packages/ray/tune/trainable/trainable.py\", line 342, in train\n",
      "    raise skipped from exception_cause(skipped)\n",
      "  File \"/home/gediminas/anaconda3/envs/DL/lib/python3.11/site-packages/ray/air/_internal/util.py\", line 91, in run\n",
      "    self._ret = self._target(*self._args, **self._kwargs)\n",
      "                ^^^^^^^^^^^^^^^^^^^^^^^^^^^^^^^^^^^^^^^^^\n",
      "  File \"/home/gediminas/anaconda3/envs/DL/lib/python3.11/site-packages/ray/tune/trainable/function_trainable.py\", line 115, in <lambda>\n",
      "    training_func=lambda: self._trainable_func(self.config),\n",
      "                          ^^^^^^^^^^^^^^^^^^^^^^^^^^^^^^^^^\n",
      "           ^^^^^^^^^^^^^^^^^^^^^^^^^^^^^^^\n",
      "  File \"/home/gediminas/anaconda3/envs/DL/lib/python3.11/site-packages/ray/tune/trainable/function_trainable.py\", line 332, in _trainable_func\n",
      "    output = fn()\n",
      "             ^^^^\n",
      "  File \"/home/gediminas/anaconda3/envs/DL/lib/python3.11/site-packages/ray/tune/trainable/util.py\", line 321, in inner\n",
      "    return trainable(config, **fn_kwargs)\n",
      "           ^^^^^^^^^^^^^^^^^^^^^^^^^^^^^^\n",
      "  File \"/tmp/ipykernel_20077/685680896.py\", line 4, in train_mnist_tune\n",
      "  File \"/home/gediminas/anaconda3/envs/DL/lib/python3.11/site-packages/pytorch_lightning/utilities/argparse.py\", line 70, in insert_env_defaults\n",
      "    return fn(self, **kwargs)\n",
      "           ^^^^^^^^^^^^^^^^^^\n",
      "TypeError: Trainer.__init__() got an unexpected keyword argument 'gpus'\n",
      "2023-12-07 11:28:35,058\tERROR tune_controller.py:1383 -- Trial task failed for trial train_mnist_tune_fc4ed_00009\n",
      "Traceback (most recent call last):\n",
      "  File \"/home/gediminas/anaconda3/envs/DL/lib/python3.11/site-packages/ray/air/execution/_internal/event_manager.py\", line 110, in resolve_future\n",
      "    result = ray.get(future)\n",
      "             ^^^^^^^^^^^^^^^\n",
      "  File \"/home/gediminas/anaconda3/envs/DL/lib/python3.11/site-packages/ray/_private/auto_init_hook.py\", line 24, in auto_init_wrapper\n",
      "    return fn(*args, **kwargs)\n",
      "           ^^^^^^^^^^^^^^^^^^^\n",
      "  File \"/home/gediminas/anaconda3/envs/DL/lib/python3.11/site-packages/ray/_private/client_mode_hook.py\", line 103, in wrapper\n",
      "    return func(*args, **kwargs)\n",
      "           ^^^^^^^^^^^^^^^^^^^^^\n",
      "  File \"/home/gediminas/anaconda3/envs/DL/lib/python3.11/site-packages/ray/_private/worker.py\", line 2563, in get\n",
      "    raise value.as_instanceof_cause()\n",
      "ray.exceptions.RayTaskError(TypeError): \u001b[36mray::ImplicitFunc.train()\u001b[39m (pid=22220, ip=192.168.0.103, actor_id=8a8cdd4c4e9afab4d60dbe6401000000, repr=train_mnist_tune)\n",
      "           ^^^^^^^^^^^^^^^^^^^^^^^^^^^^^^^^^^^^\n",
      "           ^^^^^^^^^^^^^^^^^^^^^^^^^^^^^^^\n",
      "  File \"/home/gediminas/anaconda3/envs/DL/lib/python3.11/site-packages/ray/tune/trainable/trainable.py\", line 342, in train\n",
      "    raise skipped from exception_cause(skipped)\n",
      "  File \"/home/gediminas/anaconda3/envs/DL/lib/python3.11/site-packages/ray/air/_internal/util.py\", line 91, in run\n",
      "    self._ret = self._target(*self._args, **self._kwargs)\n",
      "                ^^^^^^^^^^^^^^^^^^^^^^^^^^^^^^^^^^^^^^^^^\n",
      "  File \"/home/gediminas/anaconda3/envs/DL/lib/python3.11/site-packages/ray/tune/trainable/function_trainable.py\", line 115, in <lambda>\n",
      "    training_func=lambda: self._trainable_func(self.config),\n",
      "                          ^^^^^^^^^^^^^^^^^^^^^^^^^^^^^^^^^\n",
      "           ^^^^^^^^^^^^^^^^^^^^^^^^^^^^^^^\n",
      "  File \"/home/gediminas/anaconda3/envs/DL/lib/python3.11/site-packages/ray/tune/trainable/function_trainable.py\", line 332, in _trainable_func\n",
      "    output = fn()\n",
      "             ^^^^\n",
      "  File \"/home/gediminas/anaconda3/envs/DL/lib/python3.11/site-packages/ray/tune/trainable/util.py\", line 321, in inner\n",
      "    return trainable(config, **fn_kwargs)\n",
      "           ^^^^^^^^^^^^^^^^^^^^^^^^^^^^^^\n",
      "  File \"/tmp/ipykernel_20077/685680896.py\", line 4, in train_mnist_tune\n",
      "  File \"/home/gediminas/anaconda3/envs/DL/lib/python3.11/site-packages/pytorch_lightning/utilities/argparse.py\", line 70, in insert_env_defaults\n",
      "    return fn(self, **kwargs)\n",
      "           ^^^^^^^^^^^^^^^^^^\n",
      "TypeError: Trainer.__init__() got an unexpected keyword argument 'gpus'\n",
      "2023-12-07 11:28:35,076\tERROR tune_controller.py:1383 -- Trial task failed for trial train_mnist_tune_fc4ed_00003\n",
      "Traceback (most recent call last):\n",
      "  File \"/home/gediminas/anaconda3/envs/DL/lib/python3.11/site-packages/ray/air/execution/_internal/event_manager.py\", line 110, in resolve_future\n",
      "    result = ray.get(future)\n",
      "             ^^^^^^^^^^^^^^^\n",
      "  File \"/home/gediminas/anaconda3/envs/DL/lib/python3.11/site-packages/ray/_private/auto_init_hook.py\", line 24, in auto_init_wrapper\n",
      "    return fn(*args, **kwargs)\n",
      "           ^^^^^^^^^^^^^^^^^^^\n",
      "  File \"/home/gediminas/anaconda3/envs/DL/lib/python3.11/site-packages/ray/_private/client_mode_hook.py\", line 103, in wrapper\n",
      "    return func(*args, **kwargs)\n",
      "           ^^^^^^^^^^^^^^^^^^^^^\n",
      "  File \"/home/gediminas/anaconda3/envs/DL/lib/python3.11/site-packages/ray/_private/worker.py\", line 2563, in get\n",
      "    raise value.as_instanceof_cause()\n",
      "ray.exceptions.RayTaskError(TypeError): \u001b[36mray::ImplicitFunc.train()\u001b[39m (pid=22215, ip=192.168.0.103, actor_id=922e5a82197d54eeedcab2bf01000000, repr=train_mnist_tune)\n",
      "           ^^^^^^^^^^^^^^^^^^^^^^^^^^^^^^^^^^^^\n",
      "           ^^^^^^^^^^^^^^^^^^^^^^^^^^^^^^^\n",
      "  File \"/home/gediminas/anaconda3/envs/DL/lib/python3.11/site-packages/ray/tune/trainable/trainable.py\", line 342, in train\n",
      "    raise skipped from exception_cause(skipped)\n",
      "  File \"/home/gediminas/anaconda3/envs/DL/lib/python3.11/site-packages/ray/air/_internal/util.py\", line 91, in run\n",
      "    self._ret = self._target(*self._args, **self._kwargs)\n",
      "                ^^^^^^^^^^^^^^^^^^^^^^^^^^^^^^^^^^^^^^^^^\n",
      "  File \"/home/gediminas/anaconda3/envs/DL/lib/python3.11/site-packages/ray/tune/trainable/function_trainable.py\", line 115, in <lambda>\n",
      "    training_func=lambda: self._trainable_func(self.config),\n",
      "                          ^^^^^^^^^^^^^^^^^^^^^^^^^^^^^^^^^\n",
      "           ^^^^^^^^^^^^^^^^^^^^^^^^^^^^^^^\n",
      "  File \"/home/gediminas/anaconda3/envs/DL/lib/python3.11/site-packages/ray/tune/trainable/function_trainable.py\", line 332, in _trainable_func\n",
      "    output = fn()\n",
      "             ^^^^\n",
      "  File \"/home/gediminas/anaconda3/envs/DL/lib/python3.11/site-packages/ray/tune/trainable/util.py\", line 321, in inner\n",
      "    return trainable(config, **fn_kwargs)\n",
      "           ^^^^^^^^^^^^^^^^^^^^^^^^^^^^^^\n",
      "  File \"/tmp/ipykernel_20077/685680896.py\", line 4, in train_mnist_tune\n",
      "  File \"/home/gediminas/anaconda3/envs/DL/lib/python3.11/site-packages/pytorch_lightning/utilities/argparse.py\", line 70, in insert_env_defaults\n",
      "    return fn(self, **kwargs)\n",
      "           ^^^^^^^^^^^^^^^^^^\n",
      "TypeError: Trainer.__init__() got an unexpected keyword argument 'gpus'\n",
      "2023-12-07 11:28:35,092\tERROR tune_controller.py:1383 -- Trial task failed for trial train_mnist_tune_fc4ed_00007\n",
      "Traceback (most recent call last):\n",
      "  File \"/home/gediminas/anaconda3/envs/DL/lib/python3.11/site-packages/ray/air/execution/_internal/event_manager.py\", line 110, in resolve_future\n",
      "    result = ray.get(future)\n",
      "             ^^^^^^^^^^^^^^^\n",
      "  File \"/home/gediminas/anaconda3/envs/DL/lib/python3.11/site-packages/ray/_private/auto_init_hook.py\", line 24, in auto_init_wrapper\n",
      "    return fn(*args, **kwargs)\n",
      "           ^^^^^^^^^^^^^^^^^^^\n",
      "  File \"/home/gediminas/anaconda3/envs/DL/lib/python3.11/site-packages/ray/_private/client_mode_hook.py\", line 103, in wrapper\n",
      "    return func(*args, **kwargs)\n",
      "           ^^^^^^^^^^^^^^^^^^^^^\n",
      "  File \"/home/gediminas/anaconda3/envs/DL/lib/python3.11/site-packages/ray/_private/worker.py\", line 2563, in get\n",
      "    raise value.as_instanceof_cause()\n",
      "ray.exceptions.RayTaskError(TypeError): \u001b[36mray::ImplicitFunc.train()\u001b[39m (pid=22218, ip=192.168.0.103, actor_id=72e575815a7332daf1506a4401000000, repr=train_mnist_tune)\n",
      "           ^^^^^^^^^^^^^^^^^^^^^^^^^^^^^^^^^^^^\n",
      "           ^^^^^^^^^^^^^^^^^^^^^^^^^^^^^^^\n",
      "  File \"/home/gediminas/anaconda3/envs/DL/lib/python3.11/site-packages/ray/tune/trainable/trainable.py\", line 342, in train\n",
      "    raise skipped from exception_cause(skipped)\n",
      "  File \"/home/gediminas/anaconda3/envs/DL/lib/python3.11/site-packages/ray/air/_internal/util.py\", line 91, in run\n",
      "    self._ret = self._target(*self._args, **self._kwargs)\n",
      "                ^^^^^^^^^^^^^^^^^^^^^^^^^^^^^^^^^^^^^^^^^\n",
      "  File \"/home/gediminas/anaconda3/envs/DL/lib/python3.11/site-packages/ray/tune/trainable/function_trainable.py\", line 115, in <lambda>\n",
      "    training_func=lambda: self._trainable_func(self.config),\n",
      "                          ^^^^^^^^^^^^^^^^^^^^^^^^^^^^^^^^^\n",
      "           ^^^^^^^^^^^^^^^^^^^^^^^^^^^^^^^\n",
      "  File \"/home/gediminas/anaconda3/envs/DL/lib/python3.11/site-packages/ray/tune/trainable/function_trainable.py\", line 332, in _trainable_func\n",
      "    output = fn()\n",
      "             ^^^^\n",
      "  File \"/home/gediminas/anaconda3/envs/DL/lib/python3.11/site-packages/ray/tune/trainable/util.py\", line 321, in inner\n",
      "    return trainable(config, **fn_kwargs)\n",
      "           ^^^^^^^^^^^^^^^^^^^^^^^^^^^^^^\n",
      "  File \"/tmp/ipykernel_20077/685680896.py\", line 4, in train_mnist_tune\n",
      "  File \"/home/gediminas/anaconda3/envs/DL/lib/python3.11/site-packages/pytorch_lightning/utilities/argparse.py\", line 70, in insert_env_defaults\n",
      "    return fn(self, **kwargs)\n",
      "           ^^^^^^^^^^^^^^^^^^\n",
      "TypeError: Trainer.__init__() got an unexpected keyword argument 'gpus'\n",
      "2023-12-07 11:28:35,098\tERROR tune.py:1043 -- Trials did not complete: [train_mnist_tune_fc4ed_00000, train_mnist_tune_fc4ed_00001, train_mnist_tune_fc4ed_00002, train_mnist_tune_fc4ed_00003, train_mnist_tune_fc4ed_00004, train_mnist_tune_fc4ed_00005, train_mnist_tune_fc4ed_00006, train_mnist_tune_fc4ed_00007, train_mnist_tune_fc4ed_00008, train_mnist_tune_fc4ed_00009]\n",
      "2023-12-07 11:28:35,099\tINFO tune.py:1047 -- Total run time: 3.95 seconds (3.93 seconds for the tuning loop).\n",
      "2023-12-07 11:28:35,103\tWARNING experiment_analysis.py:575 -- Could not find best trial. Did you pass the correct `metric` parameter?\n"
     ]
    },
    {
     "name": "stdout",
     "output_type": "stream",
     "text": [
      "== Status ==\n",
      "Current time: 2023-12-07 11:28:35 (running for 00:00:03.93)\n",
      "Using AsyncHyperBand: num_stopped=0\n",
      "Bracket: Iter 8.000: None | Iter 4.000: None | Iter 2.000: None | Iter 1.000: None\n",
      "Logical resource usage: 1.0/12 CPUs, 0/1 GPUs (0.0/1.0 accelerator_type:G)\n",
      "Result logdir: /home/gediminas/ray_results/tune_mnist_asha\n",
      "Number of trials: 10/10 (10 ERROR)\n",
      "Number of errored trials: 10\n",
      "+------------------------------+--------------+--------------------------------------------------------------------------------------------------------------------------------------------------------------------+\n",
      "| Trial name                   |   # failures | error file                                                                                                                                                         |\n",
      "|------------------------------+--------------+--------------------------------------------------------------------------------------------------------------------------------------------------------------------|\n",
      "| train_mnist_tune_fc4ed_00000 |            1 | /home/gediminas/ray_results/tune_mnist_asha/train_mnist_tune_fc4ed_00000_0_batch_size=32,layer_1_size=128,layer_2_size=256,lr=0.0805_2023-12-07_11-28-31/error.txt |\n",
      "| train_mnist_tune_fc4ed_00001 |            1 | /home/gediminas/ray_results/tune_mnist_asha/train_mnist_tune_fc4ed_00001_1_batch_size=64,layer_1_size=32,layer_2_size=64,lr=0.0001_2023-12-07_11-28-31/error.txt   |\n",
      "| train_mnist_tune_fc4ed_00002 |            1 | /home/gediminas/ray_results/tune_mnist_asha/train_mnist_tune_fc4ed_00002_2_batch_size=32,layer_1_size=128,layer_2_size=128,lr=0.0076_2023-12-07_11-28-31/error.txt |\n",
      "| train_mnist_tune_fc4ed_00003 |            1 | /home/gediminas/ray_results/tune_mnist_asha/train_mnist_tune_fc4ed_00003_3_batch_size=128,layer_1_size=32,layer_2_size=256,lr=0.0267_2023-12-07_11-28-31/error.txt |\n",
      "| train_mnist_tune_fc4ed_00004 |            1 | /home/gediminas/ray_results/tune_mnist_asha/train_mnist_tune_fc4ed_00004_4_batch_size=64,layer_1_size=64,layer_2_size=128,lr=0.0019_2023-12-07_11-28-31/error.txt  |\n",
      "| train_mnist_tune_fc4ed_00005 |            1 | /home/gediminas/ray_results/tune_mnist_asha/train_mnist_tune_fc4ed_00005_5_batch_size=32,layer_1_size=128,layer_2_size=128,lr=0.0144_2023-12-07_11-28-31/error.txt |\n",
      "| train_mnist_tune_fc4ed_00006 |            1 | /home/gediminas/ray_results/tune_mnist_asha/train_mnist_tune_fc4ed_00006_6_batch_size=64,layer_1_size=128,layer_2_size=128,lr=0.0156_2023-12-07_11-28-31/error.txt |\n",
      "| train_mnist_tune_fc4ed_00007 |            1 | /home/gediminas/ray_results/tune_mnist_asha/train_mnist_tune_fc4ed_00007_7_batch_size=128,layer_1_size=32,layer_2_size=256,lr=0.0311_2023-12-07_11-28-31/error.txt |\n",
      "| train_mnist_tune_fc4ed_00008 |            1 | /home/gediminas/ray_results/tune_mnist_asha/train_mnist_tune_fc4ed_00008_8_batch_size=64,layer_1_size=128,layer_2_size=64,lr=0.0181_2023-12-07_11-28-31/error.txt  |\n",
      "| train_mnist_tune_fc4ed_00009 |            1 | /home/gediminas/ray_results/tune_mnist_asha/train_mnist_tune_fc4ed_00009_9_batch_size=64,layer_1_size=32,layer_2_size=64,lr=0.0168_2023-12-07_11-28-31/error.txt   |\n",
      "+------------------------------+--------------+--------------------------------------------------------------------------------------------------------------------------------------------------------------------+\n",
      "\n"
     ]
    },
    {
     "ename": "RuntimeError",
     "evalue": "No best trial found for the given metric: loss. This means that no trial has reported this metric, or all values reported for this metric are NaN. To not ignore NaN values, you can set the `filter_nan_and_inf` arg to False.",
     "output_type": "error",
     "traceback": [
      "\u001b[0;31m---------------------------------------------------------------------------\u001b[0m",
      "\u001b[0;31mRuntimeError\u001b[0m                              Traceback (most recent call last)",
      "\u001b[1;32m/home/gediminas/Documents/turing_projects/module4_s1/gskvar-DL.1.5/test.ipynb Cell 12\u001b[0m line \u001b[0;36m1\n\u001b[0;32m----> <a href='vscode-notebook-cell:/home/gediminas/Documents/turing_projects/module4_s1/gskvar-DL.1.5/test.ipynb#X32sZmlsZQ%3D%3D?line=0'>1</a>\u001b[0m tune_mnist_asha()\n",
      "\u001b[1;32m/home/gediminas/Documents/turing_projects/module4_s1/gskvar-DL.1.5/test.ipynb Cell 12\u001b[0m line \u001b[0;36m4\n\u001b[1;32m     <a href='vscode-notebook-cell:/home/gediminas/Documents/turing_projects/module4_s1/gskvar-DL.1.5/test.ipynb#X32sZmlsZQ%3D%3D?line=23'>24</a>\u001b[0m tuner \u001b[39m=\u001b[39m tune\u001b[39m.\u001b[39mTuner(\n\u001b[1;32m     <a href='vscode-notebook-cell:/home/gediminas/Documents/turing_projects/module4_s1/gskvar-DL.1.5/test.ipynb#X32sZmlsZQ%3D%3D?line=24'>25</a>\u001b[0m     tune\u001b[39m.\u001b[39mwith_resources(train_fn_with_parameters, resources\u001b[39m=\u001b[39mresources_per_trial),\n\u001b[1;32m     <a href='vscode-notebook-cell:/home/gediminas/Documents/turing_projects/module4_s1/gskvar-DL.1.5/test.ipynb#X32sZmlsZQ%3D%3D?line=25'>26</a>\u001b[0m     tune_config\u001b[39m=\u001b[39mtune\u001b[39m.\u001b[39mTuneConfig(\n\u001b[0;32m   (...)\u001b[0m\n\u001b[1;32m     <a href='vscode-notebook-cell:/home/gediminas/Documents/turing_projects/module4_s1/gskvar-DL.1.5/test.ipynb#X32sZmlsZQ%3D%3D?line=35'>36</a>\u001b[0m     param_space\u001b[39m=\u001b[39mconfig,\n\u001b[1;32m     <a href='vscode-notebook-cell:/home/gediminas/Documents/turing_projects/module4_s1/gskvar-DL.1.5/test.ipynb#X32sZmlsZQ%3D%3D?line=36'>37</a>\u001b[0m )\n\u001b[1;32m     <a href='vscode-notebook-cell:/home/gediminas/Documents/turing_projects/module4_s1/gskvar-DL.1.5/test.ipynb#X32sZmlsZQ%3D%3D?line=37'>38</a>\u001b[0m results \u001b[39m=\u001b[39m tuner\u001b[39m.\u001b[39mfit()\n\u001b[0;32m---> <a href='vscode-notebook-cell:/home/gediminas/Documents/turing_projects/module4_s1/gskvar-DL.1.5/test.ipynb#X32sZmlsZQ%3D%3D?line=39'>40</a>\u001b[0m \u001b[39mprint\u001b[39m(\u001b[39m\"\u001b[39m\u001b[39mBest hyperparameters found were: \u001b[39m\u001b[39m\"\u001b[39m, results\u001b[39m.\u001b[39;49mget_best_result()\u001b[39m.\u001b[39mconfig)\n",
      "File \u001b[0;32m~/anaconda3/envs/DL/lib/python3.11/site-packages/ray/tune/result_grid.py:162\u001b[0m, in \u001b[0;36mResultGrid.get_best_result\u001b[0;34m(self, metric, mode, scope, filter_nan_and_inf)\u001b[0m\n\u001b[1;32m    151\u001b[0m     error_msg \u001b[39m=\u001b[39m (\n\u001b[1;32m    152\u001b[0m         \u001b[39m\"\u001b[39m\u001b[39mNo best trial found for the given metric: \u001b[39m\u001b[39m\"\u001b[39m\n\u001b[1;32m    153\u001b[0m         \u001b[39mf\u001b[39m\u001b[39m\"\u001b[39m\u001b[39m{\u001b[39;00mmetric\u001b[39m \u001b[39m\u001b[39mor\u001b[39;00m\u001b[39m \u001b[39m\u001b[39mself\u001b[39m\u001b[39m.\u001b[39m_experiment_analysis\u001b[39m.\u001b[39mdefault_metric\u001b[39m}\u001b[39;00m\u001b[39m. \u001b[39m\u001b[39m\"\u001b[39m\n\u001b[1;32m    154\u001b[0m         \u001b[39m\"\u001b[39m\u001b[39mThis means that no trial has reported this metric\u001b[39m\u001b[39m\"\u001b[39m\n\u001b[1;32m    155\u001b[0m     )\n\u001b[1;32m    156\u001b[0m     error_msg \u001b[39m+\u001b[39m\u001b[39m=\u001b[39m (\n\u001b[1;32m    157\u001b[0m         \u001b[39m\"\u001b[39m\u001b[39m, or all values reported for this metric are NaN. To not ignore NaN \u001b[39m\u001b[39m\"\u001b[39m\n\u001b[1;32m    158\u001b[0m         \u001b[39m\"\u001b[39m\u001b[39mvalues, you can set the `filter_nan_and_inf` arg to False.\u001b[39m\u001b[39m\"\u001b[39m\n\u001b[1;32m    159\u001b[0m         \u001b[39mif\u001b[39;00m filter_nan_and_inf\n\u001b[1;32m    160\u001b[0m         \u001b[39melse\u001b[39;00m \u001b[39m\"\u001b[39m\u001b[39m.\u001b[39m\u001b[39m\"\u001b[39m\n\u001b[1;32m    161\u001b[0m     )\n\u001b[0;32m--> 162\u001b[0m     \u001b[39mraise\u001b[39;00m \u001b[39mRuntimeError\u001b[39;00m(error_msg)\n\u001b[1;32m    164\u001b[0m \u001b[39mreturn\u001b[39;00m \u001b[39mself\u001b[39m\u001b[39m.\u001b[39m_trial_to_result(best_trial)\n",
      "\u001b[0;31mRuntimeError\u001b[0m: No best trial found for the given metric: loss. This means that no trial has reported this metric, or all values reported for this metric are NaN. To not ignore NaN values, you can set the `filter_nan_and_inf` arg to False."
     ]
    }
   ],
   "source": [
    "tune_mnist_asha()"
   ]
  },
  {
   "cell_type": "code",
   "execution_count": null,
   "metadata": {},
   "outputs": [],
   "source": []
  }
 ],
 "metadata": {
  "kernelspec": {
   "display_name": "DL",
   "language": "python",
   "name": "python3"
  },
  "language_info": {
   "codemirror_mode": {
    "name": "ipython",
    "version": 3
   },
   "file_extension": ".py",
   "mimetype": "text/x-python",
   "name": "python",
   "nbconvert_exporter": "python",
   "pygments_lexer": "ipython3",
   "version": "3.11.5"
  }
 },
 "nbformat": 4,
 "nbformat_minor": 2
}
